<?xml version="1.0"?>
<robot name="ur5e">
  <link name="base_link"/>
  <link name="shoulder_link"/>
  <link name="upper_arm_link"/>
  <link name="forearm_link"/>
  <link name="wrist_1_link"/>
  <link name="wrist_2_link"/>
  <link name="wrist_3_link"/>

  <joint name="shoulder_pan_joint" type="revolute">
    <parent link="base_link"/>
    <child link="shoulder_link"/>
    <axis xyz="0 0 1"/>
    <limit lower="-6.283" upper="6.283" effort="150" velocity="2.0"/>
  </joint>

  <joint name="shoulder_lift_joint" type="revolute">
    <parent link="shoulder_link"/>
    <child link="upper_arm_link"/>
    <axis xyz="0 1 0"/>
    <limit lower="-6.283" upper="6.283" effort="150" velocity="2.0"/>
  </joint>

  <joint name="elbow_joint" type="revolute">
    <parent link="upper_arm_link"/>
    <child link="forearm_link"/>
    <axis xyz="0 1 0"/>
    <limit lower="-6.283" upper="6.283" effort="150" velocity="2.0"/>
  </joint>

  <joint name="wrist_1_joint" type="revolute">
    <parent link="forearm_link"/>
    <child link="wrist_1_link"/>
    <axis xyz="0 0 1"/>
    <limit lower="-6.283" upper="6.283" effort="28" velocity="3.0"/>
  </joint>

  <joint name="wrist_2_joint" type="revolute">
    <parent link="wrist_1_link"/>
    <child link="wrist_2_link"/>
    <axis xyz="0 1 0"/>
    <limit lower="-6.283" upper="6.283" effort="28" velocity="3.0"/>
  </joint>

  <joint name="wrist_3_joint" type="revolute">
    <parent link="wrist_2_link"/>
    <child link="wrist_3_link"/>
    <axis xyz="0 0 1"/>
    <limit lower="-6.283" upper="6.283" effort="28" velocity="3.0"/>
  </joint>
</robot>
